<?xml version="1.0"?>
<robot name="tortoisebot">
  
  <link name="base_link">
    <visual>
      <geometry>
        <box size="0.6 0.3 0.3"/>
      </geometry>
      <material name="silver">
        <color rgba="0.75 0.75 0.75 1"/>
      </material>
    </visual>

    <!-- Physical Characteristics of Robot, ada <collision> dan <inertial> -->
    <collision>
      <geometry>
        <box size="0.6 0.3 0.3"/>
      </geometry>
    </collision>
    
    <!-- Tambahan program untuk inersia chassis -->
    <inertial>
      <mass value="1.0"/>
      <inertia ixx="0.015" iyy="0.0375" izz="0.0375" ixy="0" ixz="0" iyz="0"/>
    </inertial>
        
        <!-- TIPS -->
        <!-- When	working	with	inertial	values,	heres	a	great	way	to	visually	debug	things	is	in	Gazebo	click	on -->
        <!-- View > Center	of	Mass/Inertia	to	see	a	visual	representation	of	the	inertia	matrix	and	mass	for	each	link	in -->
        <!-- your	robot.	If	the	inertial	data	is	very	different	from	(e.g.,	much	smaller	or	larger	than)	the	visual	or -->
        <!-- collision	geometry,	then	you	have	a	problem. -->

    <!-- Tambahan program untuk inersia -->
    
    <!-- Physical Characteristics of Robot, ada <collision> dan <inertial> -->

  </link>

      

      
  <!-- Membuat dudukan caster depan -->
  <link name="front_caster">
    <visual>
      <geometry>
        <box size="0.1 0.1 0.1"/>
      </geometry>
      <material name="silver"/>
    </visual>
    
    <!-- Physical Characteristics of Robot, ada <collision> dan <inertial> -->
    <collision>
      <geometry>
        <box size="0.1 0.1 0.1"/>
      </geometry>
    </collision>
    
    <!-- Tambahan program untuk inersia dudukan caster -->
    <inertial>
      <mass value="0.1"/>
      <inertia ixx="0.00083" iyy="0.00083" izz="0.000167" ixy="0" ixz="0" iyz="0"/>
    </inertial>
    <!-- <inertial>      
      <mass value="0.1" />
      <inertia ixx="1.1175580e-05" ixy="-4.2369783e-11" ixz="0"
               iyy="1.1192413e-05" iyz="0"
               izz="0.000167" />
    </inertial> -->
    <!-- Tambahan program untuk inersia dudukan caster -->

    <!-- Physical Characteristics of Robot, ada <collision> dan <inertial> -->

  </link>

  <joint name="front_caster_joint" type="fixed">
    <axis xyz="0 0 1"/>
    <parent link="base_link"/>
    <child link="front_caster"/>
    <origin xyz="0.3 0.0 -0.1" rpy="0.0 0.0 0.0"/>
  </joint>
  <!-- Membuat dudukan caster depan -->

  <!-- Membuat ban caster -->
  <link name="front_wheel">
    <visual>
      <geometry>
        <cylinder radius="0.035" length="0.05"/>
      </geometry>
      <material name="red">
        <color rgba="1 0 0 1"/>
      </material>
    </visual>
    
    <!-- Physical Characteristics of Robot, ada <collision> dan <inertial> -->
    <collision>
      <geometry>
        <cylinder radius="0.035" length="0.05"/>
      </geometry>
    </collision>
    
    <!-- Tambahan program untuk inersia caster -->
    <inertial>
      <mass value="0.1"/>
      <inertia ixx="5.1458e-5" iyy="5.1458e-5" izz="6.125e-5" ixy="0" ixz="0" iyz="0"/>
    </inertial>
    <!-- <inertial>      
      <mass value="2.8498940e-02" />
      <inertia ixx="1.1175580e-05" ixy="-4.2369783e-11" ixz="-5.9381719e-09"
               iyy="1.1192413e-05" iyz="-1.4400107e-11"
               izz="2.0712558e-05" />
    </inertial> -->
    <!-- Tambahan program untuk inersia caster -->

    <!-- Physical Characteristics of Robot, ada <collision> dan <inertial> -->

  </link>

  <joint name="front_wheel_joint" type="continuous">
    <axis xyz="0.0 0.0 1"/>
    <parent link="front_caster"/>
    <child link="front_wheel"/>
    <origin xyz="0.05 0.0 -0.05" rpy="-1.5708 0.0 0.0"/>
  </joint>
  <!-- Membuat ban caster -->

  <!-- Membuat Ban Belakang -->
  <link name="right_wheel">
    <visual>
      <geometry>
        <cylinder radius="0.035" length="0.05"/>
      </geometry>
      <material name="green">
        <color rgba="0.0 1.0 0.0 1.0"/>
      </material>
    </visual>
    
    <!-- Physical Characteristics of Robot, ada <collision> dan <inertial> -->
    <collision>
      <geometry>
        <cylinder radius="0.035" length="0.05"/>
      </geometry>
    </collision>
    
    <!-- Tambahan program untuk inersia ban kanan -->
    <!-- <inertial>
      <mass value="0.1"/>
      <inertia ixx="5.1458e-5" iyy="5.1458e-5" izz="6.125e-5" ixy="0" ixz="0" iyz="0"/>
    </inertial> -->

    <inertial>      
      <mass value="2.8498940e-02" />
      <inertia ixx="1.1175580e-05" ixy="-4.2369783e-11" ixz="-5.9381719e-09"
               iyy="1.1192413e-05" iyz="-1.4400107e-11"
               izz="2.0712558e-05" />
    </inertial>
    
    <!-- Tambahan program untuk inersia ban kanan -->

    <!-- Physical Characteristics of Robot, ada <collision> dan <inertial> -->

  </link>

  <joint name="right_wheel_joint" type="continuous">
    <axis xyz="0.0 0.0 1"/>
    <parent link="base_link"/>
    <child link="right_wheel"/>
    <origin xyz="-0.2825 -0.125 -.15" rpy="-1.5708 0.0 0.0"/>
  </joint>

  <link name="left_wheel">
    <visual>
      <geometry>
        <cylinder radius="0.035" length="0.05"/>
      </geometry>
      <material name="blue">
        <color rgba="0.0 0.0 1.0 1.0"/>
      </material>
    </visual>
    
    <!-- Physical Characteristics of Robot, ada <collision> dan <inertial> -->
    <collision>
      <geometry>
        <cylinder radius="0.035" length="0.05"/>
      </geometry>
    </collision>

    <!-- Tambahan program untuk inersia ban kanan -->
    <!-- <inertial> -->
      <!-- <mass value="0.1"/> -->
      <!-- <inertia ixx="5.1458e-5" iyy="5.1458e-5" izz="6.125e-5" ixy="0" ixz="0" iyz="0"/> -->
    <!-- </inertial> -->
    
    <inertial>      
      <mass value="2.8498940e-02" />
      <inertia ixx="1.1175580e-05" ixy="-4.2369783e-11" ixz="-5.9381719e-09"
               iyy="1.1192413e-05" iyz="-1.4400107e-11"
               izz="2.0712558e-05" />
    </inertial>
    <!-- Tambahan program untuk inersia ban kanan -->
    
    <!-- Physical Characteristics of Robot, ada <collision> dan <inertial> -->

  </link>

  <joint name="left_wheel_joint" type="continuous">
    <axis xyz="0.0 0.0 1"/>
    <parent link="base_link"/>
    <child link="left_wheel"/>
    <origin xyz="-0.2825 0.125 -.15" rpy="-1.5708 0.0 0.0"/>
  </joint>
  <!-- Membuat Ban Belakang -->



  <!-- Tambah controller, supaya bisa bergerak di gazebo dengan menggunakan cmd_vel/odom -->
  <gazebo>
    <plugin name="differential_drive_controller"
            filename="libgazebo_ros_diff_drive.so">
      <leftJoint>right_wheel_joint</leftJoint>
      <rightJoint>left_wheel_joint</rightJoint>
      <robotBaseFrame>base_link</robotBaseFrame>
      <wheelSeparation>0.25</wheelSeparation>
      <wheelDiameter>0.07</wheelDiameter>
      <publishWheelJointState>true</publishWheelJointState>
    </plugin>
  </gazebo>
  <!-- Tambah controller, supaya bisa bergerak di gazebo dengan menggunakan cmd_vel/odom -->

</robot>
